<?xml version="1.0"?>
<robot name="orne_box">

	<!-- 定数の定義 -->
	<property name="PI" value="3.1415926535897931"/>

	<!-- 色の定義 -->
	<material name="black">
		<color rgba="0.0 0.0 0.0 1.0"/>
	</material>
	<material name="brown">
		<color rgba="0.87 0.81 0.76 1.0"/>
	</material>
	<material name="red">
		<color rgba="0.8 0.0 0.0 1.0"/>
	</material>
	<material name="orange">
		<color rgba="1.0 0.42 0.04 1.0"/>
	</material>
	<material name="yellow">
		<color rgba="0.8 0.8 0.0 1.0"/>
	</material>
	<material name="green">
		<color rgba="0.0 0.8 0.0 1.0"/>
	</material>
	<material name="cyan">
		<color rgba="0.0 0.8 0.8 1.0"/>
	</material>
	<material name="blue">
		<color rgba="0.0 0.0 0.8 1.0"/>
	</material>
	<material name="purple">
		<color rgba="0.8 0.0 0.8 1.0"/>
	</material>
	<material name="gray">
		<color rgba="0.5 0.5 0.5 1.0"/>
	</material>
	<material name="white">
		<color rgba="1.0 1.0 1.0 1.0"/>
	</material>

	<!-- base_footprint -->
	<link name="base_footprint"/>
	<joint name="base_joint" type="fixed">
		<origin xyz="0.0 0.0 0.0"/>
		<parent link="base_footprint"/>
		<child link="base_link"/>
	</joint>

	<!-- base_link -->
	<link name="base_link">
		<visual>
			<origin xyz="0.090 0 0.1715" rpy="0 0 0"/>
			<geometry>
				<box size="0.400 0.404 0.202"/>
			</geometry>
			<material name="orange"/>
		</visual>
		<visual>
			<origin xyz="0.36125 0 0.2625" rpy="0 0 0"/>
			<geometry>
				<box size="0.1425 0.404 0.020"/>
			</geometry>
			<material name="orange"/>
		</visual>
		<visual>
			<origin xyz="0.35625 0 0.156" rpy="0 0 0"/>
			<geometry>
				<box size="0.1325 0.404 0.020"/>
			</geometry>
			<material name="orange"/>
		</visual>
		<visual>
			<origin xyz="-0.120 0 0.4815" rpy="0 0 0"/>
			<geometry>
				<box size="0.020 0.404 0.822"/>
			</geometry>
			<material name="orange"/>
		</visual>
		<collision>
			<origin xyz="0.090 0 0.1715" rpy="0 0 0"/>
			<geometry>
				<box size="0.400 0.404 0.202"/>
			</geometry>
		</collision>
		<collision>
			<origin xyz="0.36125 0 0.2625" rpy="0 0 0"/>
			<geometry>
				<box size="0.1425 0.404 0.020"/>
			</geometry>
		</collision>
		<collision>
			<origin xyz="0.35625 0 0.156" rpy="0 0 0"/>
			<geometry>
				<box size="0.1325 0.404 0.020"/>
			</geometry>
		</collision>
		<collision>
			<origin xyz="-0.120 0 0.4815" rpy="0 0 0"/>
			<geometry>
				<box size="0.020 0.404 0.822"/>
			</geometry>
		</collision>
		<inertial>
			<origin xyz="0.090 0 0.1715" rpy="0 0 0"/>
			<mass value="25.0"/>
			<inertia ixx="1.12" ixy="0.0" ixz="0.0" iyy="3.46" iyz="0.0" izz="3.9"/>
		</inertial>
	</link>

	<!-- キャスターのスイベルリンク -->
	<link name="left_caster_swivel_link">
		<visual>
			<origin xyz="0 0 0" rpy="0 0 0"/>
			<geometry>
				<box size="0.05 0.05 0.01"/>
			</geometry>
			<material name="purple"/>
		</visual>
		<collision>
			<origin xyz="0 0 0" rpy="0 0 0"/>
			<geometry>
				<box size="0.05 0.05 0.01"/>
			</geometry>
		</collision>
		<inertial>
			<origin xyz="0 0 0"/>
			<mass value="0.1"/>
			<inertia ixx="0.001" ixy="0.0" ixz="0.0" iyy="0.001" iyz="0.0" izz="0.001"/>
		</inertial>
	</link>

	<link name="right_caster_swivel_link">
		<visual>
			<origin xyz="0 0 0" rpy="0 0 0"/>
			<geometry>
				<box size="0.05 0.05 0.01"/>
			</geometry>
			<material name="purple"/>
		</visual>
		<collision>
			<origin xyz="0 0 0" rpy="0 0 0"/>
			<geometry>
				<box size="0.05 0.05 0.01"/>
			</geometry>
		</collision>
		<inertial>
			<origin xyz="0 0 0"/>
			<mass value="0.1"/>
			<inertia ixx="0.001" ixy="0.0" ixz="0.0" iyy="0.001" iyz="0.0" izz="0.001"/>
		</inertial>
	</link>

	<!-- キャスターの車輪リンク -->
	<link name="left_caster_wheel_link">
		<visual>
			<origin xyz="0 0 0" rpy="0 0 0"/>
			<geometry>
				<cylinder length="0.025" radius="0.050"/>
			</geometry>
			<material name="purple"/>
		</visual>
		<collision>
			<origin xyz="0 0 0" rpy="0 0 0"/>
			<geometry>
				<cylinder length="0.025" radius="0.050"/>
			</geometry>
		</collision>
		<inertial>
			<origin xyz="0 0 0"/>
			<mass value="0.2"/>
			<inertia ixx="0.001" ixy="0.0" ixz="0.0" iyy="0.001" iyz="0.0" izz="0.001"/>
		</inertial>
	</link>

	<link name="right_caster_wheel_link">
		<visual>
			<origin xyz="0 0 0" rpy="0 0 0"/>
			<geometry>
				<cylinder length="0.025" radius="0.050"/>
			</geometry>
			<material name="purple"/>
		</visual>
		<collision>
			<origin xyz="0 0 0" rpy="0 0 0"/>
			<geometry>
				<cylinder length="0.025" radius="0.050"/>
			</geometry>
		</collision>
		<inertial>
			<origin xyz="0 0 0"/>
			<mass value="0.2"/>
			<inertia ixx="0.001" ixy="0.0" ixz="0.0" iyy="0.001" iyz="0.0" izz="0.001"/>
		</inertial>
	</link>

	<!-- 左キャスターとジョイント -->
	<joint name="left_caster_swivel_joint" type="continuous">
		<parent link="base_link"/>
		<child link="left_caster_swivel_link"/>
		<origin xyz="0.362 0.150 0.115" rpy="0 0 0"/>
		<axis xyz="0 0 1"/>
		<limit effort="0.0" velocity="0.0" lower="-1e15" upper="1e15"/>
		<dynamics damping="0.01"/>
	</joint>

	<joint name="left_caster_wheel_joint" type="continuous">
		<parent link="left_caster_swivel_link"/>
		<child link="left_caster_wheel_link"/>
		<origin xyz="0.03 0.0 -0.065" rpy="-1.5708 0 0"/>
		<axis xyz="0 0 1"/>
		<limit effort="0.0" velocity="0.0" lower="-1e15" upper="1e15"/>
		<dynamics damping="0.01"/>
	</joint>

	<!-- 右キャスターとジョイント -->
	<joint name="right_caster_swivel_joint" type="continuous">
		<parent link="base_link"/>
		<child link="right_caster_swivel_link"/>
		<origin xyz="0.362 -0.150 0.115" rpy="0 0 0"/>
		<axis xyz="0 0 1"/>
		<limit effort="0.0" velocity="0.0" lower="-1e15" upper="1e15"/>
		<dynamics damping="0.01"/>
	</joint>

	<joint name="right_caster_wheel_joint" type="continuous">
		<parent link="right_caster_swivel_link"/>
		<child link="right_caster_wheel_link"/>
		<origin xyz="0.03 0.0 -0.065" rpy="-1.5708 0 0"/>
		<axis xyz="0 0 1"/>
		<limit effort="0.0" velocity="0.0" lower="-1e15" upper="1e15"/>
		<dynamics damping="0.01"/>
	</joint>

	<!-- 左ホイール -->
	<link name="wheel_left_link">
		<visual>
			<origin xyz="0.0 0.0 0.0" rpy="0 0 0"/>
			<geometry>
				<cylinder length="0.045" radius="0.152"/>
			</geometry>
			<material name="white"/>
		</visual>
		<collision>
			<origin xyz="0.0 0.0 0.0" rpy="0 0 0"/>
			<geometry>
				<cylinder length="0.045" radius="0.152"/>
			</geometry>
		</collision>
		<inertial>
			<origin xyz="0 0 0"/>
			<mass value="0.15"/>
			<inertia ixx="0.005" ixy="0.0" ixz="0.0" iyy="0.005" iyz="0.0" izz="0.01"/>
		</inertial>
	</link>

	<joint name="left_wheel_joint" type="continuous">
		<parent link="base_link"/>
		<child link="wheel_left_link"/>
		<origin xyz="0.0 0.23075 0.152" rpy="-1.5708 0 0"/>
		<axis xyz="0 0 1"/>
		<limit effort="10.5" velocity="10.0" lower="-1e15" upper="1e15"/>
		<dynamics damping="0.05"/>
	</joint>

	<!-- 右ホイール -->
	<link name="wheel_right_link">
		<visual>
			<origin xyz="0.0 0.0 0.0" rpy="0 0 0"/>
			<geometry>
				<cylinder length="0.045" radius="0.152"/>
			</geometry>
			<material name="white"/>
		</visual>
		<collision>
			<origin xyz="0.0 0.0 0.0" rpy="0 0 0"/>
			<geometry>
				<cylinder length="0.045" radius="0.152"/>
			</geometry>
		</collision>
		<inertial>
			<origin xyz="0 0 0"/>
			<mass value="0.15"/>
			<inertia ixx="0.005" ixy="0.0" ixz="0.0" iyy="0.005" iyz="0.0" izz="0.01"/>
		</inertial>
	</link>

	<joint name="right_wheel_joint" type="continuous">
		<parent link="base_link"/>
		<child link="wheel_right_link"/>
		<origin xyz="0.0 -0.23075 0.152" rpy="-1.5708 0 0"/>
		<axis xyz="0 0 1"/>
		<limit effort="10.5" velocity="10.0" lower="-1e15" upper="1e15"/>
		<dynamics damping="0.05"/>
	</joint>

	<!-- IMUセンサー -->
	<link name="imu_link">
		<inertial>
			<origin xyz="0.0 0.0 0.0"/>
			<mass value="0.005"/>
			<inertia ixx="0.001" ixy="0.0" ixz="0.0" iyy="0.001" iyz="0.0" izz="0.001"/>
		</inertial>
		<visual>
			<origin xyz="0 0 0"/>
			<geometry>
				<box size="0.05 0.05 0.05"/>
			</geometry>
			<material name="green"/>
		</visual>
	</link>

	<joint name="imu_joint" type="fixed">
		<parent link="base_link"/>
		<child link="imu_link"/>
		<origin xyz="-0.04 0.0 0.28"/>
	</joint>

	<!-- Hokuyo LiDAR -->
	<link name="mirror_lidar_link">
		<inertial>
			<origin xyz="0.0 0.0 0.0" rpy="0.0 0.0 0.0"/>
			<mass value="0.2"/>
			<inertia ixx="0.005" ixy="0.0" ixz="0.0" iyy="0.005" iyz="0.0" izz="0.005"/>
		</inertial>
		<visual>
			<origin xyz="0.0 0.0 0.0" rpy="0.0 0.0 0.0"/>
			<geometry>
				<box size="0.05 0.05 0.05"/>
			</geometry>
			<material name="black"/>
		</visual>
	</link>

	<joint name="mirror_lidar_joint" type="fixed">
		<parent link="base_link"/>
		<child link="mirror_lidar_link"/>
		<origin xyz="0.43 0.0 0.34" rpy="0 0.314 0"/>
	</joint>

	<!-- 3D-LiDAR (RFans-16) -->
	<link name="surestar">
		<inertial>
			<origin xyz="0.0 0.0 0.0" rpy="0.0 0.0 0.0"/>
			<mass value="0.3"/>
			<inertia ixx="0.01" ixy="0.0" ixz="0.0" iyy="0.01" iyz="0.0" izz="0.01"/>
		</inertial>
		<visual name="surestar_visual">
			<origin xyz="0.0 0.0 0.0" rpy="0.0 0.0 0.0"/>
			<geometry>
				<cylinder radius="0.06" length="0.1"/>
			</geometry>
			<material name="yellow"/>
		</visual>
		<collision name="surestar_collision">
			<origin xyz="0.0 0.0 0.0" rpy="0.0 0.0 0.0"/>
			<geometry>
				<cylinder radius="0.06" length="0.13"/>
			</geometry>
		</collision>
	</link>

	<joint name="surestar_joint" type="fixed">
		<origin xyz="-0.12 0.0 0.60" rpy="0.0 0.0 0.0"/>
		<parent link="base_link"/>
		<child link="surestar"/>
	</joint>

	<gazebo reference="surestar">
		<sensor name="surestar" type="gpu_lidar">
			<alwaysOn>1</alwaysOn>
			<update_rate>10</update_rate>
			<visualize>true</visualize>
			<lidar>
				<scan>
					<horizontal>
						<!-- Correct points of 1875 -->
						<samples>722</samples>
						<resolution>1</resolution>
						<min_angle>-3.141592</min_angle>
						<max_angle>3.141592</max_angle>
					</horizontal>
					<vertical>
						<samples>16</samples>
						<resolution>1</resolution>
						<min_angle>-0.261799</min_angle>
						<max_angle>0.261799</max_angle>
					</vertical>
				</scan>
				<range>
					<min>0.3</min>
					<max>100.0</max>
					<resolution>0.001</resolution>
				</range>
				<noise>
					<noise>gaussian</noise>
					<mean>0.0</mean>
					<stddev>0.02</stddev>
				</noise>
			</lidar>
			<topic>model/orne_box/rfans</topic>
		</sensor>
	</gazebo>

</robot>
